Workbook

Sheet How to use
B1: Tutor class & payment tracker
B3: 1. PAYMENT SUMMARY — type each tutor's name once in the yellow Tutor column. Set the payment period start and end (yellow cells). The sheet counts each tutor's completed classes in the period. Mark Paid? = Yes once you process the payment.
B4: 2. CLASS LOG — log every class: date, time (e.g., 18:00 - 19:30), tutor (dropdown, fed from the Payment Summary tutor list), student or class name, lesson content, recording link, status, and feedback. Row numbers compute automatically.
B5: 3. Mark a class "Completed" only after you have verified the recording — only Completed classes are counted for payment.
B7: Color legend: blue text = cells you type into · black = automatic formulas, do not edit · yellow fill = key inputs.
B8: The first Class Log row (Nguyen Van A) is an example of the expected format — replace it with real data.

Sheet Class Log
A1: No. | B1: Date | C1: Number of hours | D1: Time | E1: Tutor | F1: Student / Class | G1: Lesson content | H1: Recording link | I1: Payment | J1: Status | K1: Feedback | L1: Check thanh toán (Giang)
A2: 1 | B2: 46209 | C2: 1.5 | D2: 19:00 - 20:30 | E2: Duy | F2: Economics IGCSE | G2: Syllabus + Exam illustration and Entrance Quiz | I2: Yes | J2: Completed | K2: @Chi Vũ dạ Cô ơi, tuần này con đã dạy cho bé Châu Anh được 3 buổi, bao gồm: - Buổi 1: giới thiệu về kì thi ICGSE và test kiến thức đầu vào của bé. - Buổi 2: bé được hướng dẫn nhập môn kinh tế học, tại sao học kinh tế, kinh tế học giải quyết vấn đề gì và phân biệt các loại hàng hoá trong kinh tế học ạ. - Buổi 3: bé được học về factors of production, nhận diện từng factor trong kinh tế học và làm quen với đọc biểu đồ đơn giản ạ. Tổng kết lại thì bé có nền tảng tốt để học Economics nhờ background đã học Business trước đây nên một số thứ bé đã quen. Tuy nhiên, cách trả lời câu hỏi của bé cần phải định hướng tốt hơn để được tối đa điểm trong phòng thi do bé thường trả lời chưa đầy đủ do hay bỏ qua những từ khoá chính trong câu hỏi ạ. Tuần sau bé sẽ tạm nghỉ do phải tham gia bootcamp của VinUni, ngày 20/7 bọn con sẽ bắt đầu lại ạ. Chúc Cô và em cuối tuần thật nhiều niềm vui ạ. @Eggtree nhớ xem lại bài nhé em
A3: 2 | B3: 46211 | C3: 1.5 | D3: 19:00 - 20:30 | E3: Duy | F3: Economics IGCSE | G3: Introduction to Economics + Nature of Economics Problem | I3: Yes | J3: Completed
A4: 3 | B4: 46213 | C4: 1.5 | D4: 19:00 - 20:30 | E4: Duy | F4: Economics IGCSE | G4: Factors of Production | I4: Yes | J4: Completed
A5: 4 | B5: 46223 | C5: 1.5 | D5: 10:00 - 11:30 | E5: Duy | F5: Economics IGCSE | G5: Opportunity Cost | I5: Yes | J5: Completed | K5: @Chi Vũ Dạ Cô ơi con xin phép tổng kết tình hình học của bé Châu Anh tuần này ạ Buổi 1 (20/7): bé được học về opportunity cost, làm quen với các dạng bài toán về opportunity cost. Phần này đi con dạy kĩ vì đề thi xuất hiện khá nhiều, khoảng 2-4 câu mỗi năm ạ. Buổi 2 (22/7): bé được học về production possibility curve, bé đã học cách đọc số liệu từ đồ thị và visualize trade off bằng đồ thị. Đây cũng là một phần rất quan trọng trong đề thi, đặc biệt là phần tự luận nên con cũng đã dạy khá kỹ. Buổi 3 (24/7): bé được review lại toàn bộ section 1 (nature of economics) và chơi Quizziz để tổng kết kiến thức. @Eggtree ơi, weekly quiz của em tuần này anh để trong link này nhé, em dành tầm 15p để làm cho nhớ bài nha. Câu 1 thì em cố gắng vẽ hình rồi chụp up lên nhé, đi thi cũng sẽ yêu cầu em vẽ hình như vậy á: https://docs.google.com/forms/d/1GuUq1rzz9-912IvytbUEC35dPDOmfZHyb0ZbznpPEX8/edit Con chúc Cô và bé một cuối tuần vui vẻ ạ! | L5: Quiz
A6: 5 | B6: 46225 | C6: 1.5 | D6: 10:00 - 11:30 | E6: Duy | F6: Economics IGCSE | G6: Production Possibility Curves + Exam preparation | I6: Yes | J6: Completed
A7: 6 | B7: 46227 | C7: 1.5 | D7: 10:00 - 11:30 | E7: Duy | F7: Economics IGCSE | G7: Review session 1 | I7: Yes | J7: Completed
A8: 7 | B8: 46230 | C8: 1.5 | D8: 10:00 - 11:30 | E8: Duy | F8: Economics IGCSE | G8: How Market Works + mid-course evaluation | I8: Yes | J8: Completed | K8: @Chi Vũ Dạ Cô ơi con xin phép tổng kết tình hình học của bé Châu Anh tuần này ạ Buổi 1 (27/7): bé bắt đầu học section 2, giới thiệu về cách thị trường vận hành và làm form đánh giá cách dạy + tài liệu học giữa kì để con cải thiện phương pháp dạy và cách tiếp cận. Buổi 2 (29/7): bé được học về demand side, những nhân tố tác động đến demand và vẽ graph. Buổi 3 (30/7): bé được về về supply side và equilibrium market, cũng như đọc số liệu, vẽ graph đối với dạng bài có surplus và shortage. Đây là phần trọng tâm của chương này khi đi thi ạ. @Eggtree ơi, weekly quiz tuần này ở trong link này nha em: https://forms.gle/BdeX9CHwBw3YPKwQ8 Con chúc Cô và bé một cuối tuần nhiều niềm vui ạ!
A9: 8 | B9: 46232 | C9: 1.5 | D9: 10:00 - 11:30 | E9: Duy | F9: Economics IGCSE | G9: Demand side + Equilibrium | H9: A-level Econs Châu Anh - 2026/07/30 04:54 CEST – Recording 2 | I9: Yes | J9: Completed
A10: 9 | B10: 46234 | C10: 1.5 | D10: 10:00 - 11:30 | E10: Duy | F10: Economics IGCSE | G10: Supply side + Equilibrium state | H10: A-level Econs Châu Anh - 2026/08/03 04:57 CEST – Recording | I10: Yes | J10: Completed | L10: Quiz
A11: 10 | B11: 46237 | C11: 1.5 | D11: 10:00 - 11:30 | E11: Duy | F11: Economics IGCSE | G11: Changes in Price: Supply and Demand interaction | H11: A-level Econs Châu Anh - 2026/08/05 04:57 CEST – Recording | I11: Yes | J11: Completed | K11: @Chi Vũ Dạ Cô ơi con xin phép tổng kết tình hình học của bé Châu Anh tuần này ạ Buổi 1 (3/8): bé được học về demand and supply interaction, đi sâu vào phần interaction từ 2 phía của thị trường cũng như là học kĩ phần đọc diagram và table ạ. Buổi 2 (6/8) và Buổi 3 (7/8): theo con quan sát và nguyện vọng của bé thì bé còn chưa vững phần section 2 này nên 2 buổi này 2 anh em tập trung review kiến thức của toàn bộ section và giải đề thi thật có liên quan đến phần Supply & Demand ạ. @Eggtree ơi, em làm thêm bài tập ở đây nha: https://docs.google.com/forms/d/e/1FAIpQLSey-bRD1D1YKwu8QaQSSG0lluGZr1oXjc2xtssahQOw4Iu3cg/viewform Những cầu diagram thì em chịu khó nhìn từ file này hộ anh nhé. Con chúc Cô và bé một cuối tuần vui vẻ ạ!
A12: 11 | B12: 46240 | C12: 1.5 | D12: 10:00 - 11:30 | E12: Duy | F12: Economics IGCSE | G12: Review Supply and Demand (part 1) | H12: A-level Econs Châu Anh - 2026/08/06 04:57 CEST – Recording | I12: Yes | J12: Completed
A13: =IF(B13="","",ROW()-1) -> 12 | B13: 46241 | C13: 1.5 | D13: 10:00 - 11:30 | E13: Duy | F13: Economics IGCSE | G13: Review Supply and Demand (part 2) | H13: A-level Econs Châu Anh - 2026/08/07 04:57 CEST – Recording | I13: Yes | J13: Completed
A14: 13 | B14: 46247 | C14: 2 | D14: 16:00 - 18:15 | E14: Duy | F14: Economics IGCSE | G14: Price Elasticity of Demand | H14: A-level Econs Châu Anh - 2026/08/13 10:56 CEST – Recording 2 | I14: Yes | J14: Completed | K14: @Chi Vũ Dạ Cô ơi con xin phép tổng kết tình hình học của bé Châu Anh tuần này ạ Buổi 1 (13/8): bé được học về Price Elasticity of Demand, đi sâu vào mechanism, cách tính và các tác nhân ảnh hưởng đến nó ạ. Buổi 2 (15/8): bé được học nốt Price Elasticity of Demand, kết thúc Section 2 và học được 1/2 bài đầu tiên của Section 3 The Market Economics System ạ. 2 anh em cũng dành 15p ra để con check lại việc học trên lớp, nguyện vọng, và định hướng tương lai của bé ạ. @Eggtree ơi, bài tập tuần này là những câu còn lại về elasticity trong file này nha em. Con chúc Cô và em một cuối tuần vui vẻ ạ!
A15: 14 | B15: 46249 | C15: 2 | D15: 09:45 - 12:00 | E15: Duy | F15: Economics IGCSE | G15: Price Elasticity of Supply + 1/2 The Market Economics System | H15: Link lỗi :( | I15: Yes | J15: Completed
A16: 15 | B16: 46252 | C16: 2 | D16: 16:00 - 18:15 | E16: Duy | F16: Economics IGCSE | G16: 1/2 Market Economics System + Hướng dẫn bài trên lớp | H16: A-level Econs Châu Anh - 2026/08/18 11:54 CEST – Recording | I16: Yes | J16: Completed | K16: @Chi Vũ dạ Cô ơi, con xin phép update tình hình học tập tuần này của em Châu Anh ạ: Buổi 1 (18/8): Em được học nốt phần còn lại của The Market Economics System và con cũng dành thời gian để khảo lại bài trên lớp cũng như update giáo trình cho khớp với những gì em học ạ. Buổi 2 (20/8): Em được học về phần Market Failure, cơ chế và một số cách hạn chế Market Failure xảy ra được thực hiện bởi nhà nước ạ. @Eggtree bài tập tuần này trong link này nha em: https://docs.google.com/forms/d/e/1FAIpQLScWp39J8RzhqwKKtPQf7oVXwotcM_EOn4vkQUuwUO3reWonag/viewform Con chúc cô và em một cuối tuần vui vẻ ạ!
A17: 16 | B17: 46254 | C17: 2 | D17: 13:30 - 15:45 | E17: Duy | F17: Economics IGCSE | G17: Market Failure - Why Invisible Hand Fail | H17: A-level Econs Châu Anh - 2026/08/20 08:35 CEST – Recording | I17: Yes | J17: Completed
A18: 17 | B18: 46261 | C18: 2 | D18: 16:00 - 18:00 | E18: Duy | F18: Economics IGCSE | G18: Review Section 2 | H18: A-level Econs Châu Anh - 2026/08/27 10:57 CEST – Recording | I18: Checking | J18: Completed | K18: Dạ Cô @Chi Vũ ơi, cháu xin phép báo cáo tình hình học tập tuần này của bé Châu Anh ạ: Buổi 1 (1/9): Em được học về Mixed Economy, cách hoạt động và hiểu thêm về mô hình kinh tế phổ biến nhất ạ. Kèm theo đó con cũng khảo bài trên lớp của em luôn ạ Buổi 2 (3/9): Em được làm bài tập về toàn bộ những phần Market Economic, Market Failure và Mixed Economy ạ. Buổi 3 (5/9): em được học về Money và Banking, tìm hiểu về nguồn gốc của tiền tệ, vai trò của ngân hàng trong kinh tế học ạ @Eggtree ơi, link bài tập tuần này đây nha em. Cố gắng làm bài tập nhiều thì mới giỏi lên được và đỗ trường tốt nhé https://docs.google.com/forms/d/e/1FAIpQLSeZ3LQZNqMTGhis0jVw_uZvdt-FHqkVb4SB5KOphWhDZBs2ew/viewform?usp=sharing&ouid=111010156552142916059 Con chúc Cô và em một cuối tuần vui vẻ ạ
A19: 18 | B19: 46265 | C19: 2 | D19: 15:00 - 17:00 | E19: Duy | F19: Economics IGCSE | G19: Mixed Market + Hướng dẫn bài trên lớp | H19: A-level Econs Châu Anh - 2026/08/31 10:23 CEST – Recording | I19: Checking | J19: Completed
A20: 19 | B20: 46268 | C20: 2 | D20: 16:00 - 18:00 | E20: Duy | F20: Economics IGCSE | G20: Writing Essay Correction | H20: A-level Econs Châu Anh - 2026/09/03 11:20 CEST – Recording | I20: Checking | J20: Completed
A21: 20 | B21: 46270 | C21: 2 | D21: 10:00 - 12:00 | E21: Duy | F21: Economics IGCSE | G21: Money and Banking | H21: A-level Econs Châu Anh - 2026/09/05 04:57 CEST – Recording | I21: Checking | J21: Completed
A22: 21 | B22: 46275 | C22: 2 | D22: 16:00 - 18:00 | E22: Duy | F22: Economics IGCSE | G22: Households: Spend, Save or Borrow? (Household Economics) | H22: A-level Econs Châu Anh - 2026/09/10 10:47 CEST – Recording | I22: Checking | J22: Completed | K22: Dạ Cô @Chi Vũ ơi, con xin phép báo cáo tình hình học tập tuần này của bé Châu Anh ạ: Buổi 1 (10/9): Em được học về Household Economics, cách một hộ gia đình chi tiêu và các yếu tố ảnh hưởng. Buổi 2 (3/9): Em được học về Labor Economics, tìm hiểu về nguồn gốc của sự phân công lao động và các yếu tố ảnh hưởng đến người lao động ạ Buổi 3 (5/9): em được ôn tập về toàn bộ phần Labor và Household Economics ạ @Eggtree ơi, link bài tập tuần này đây nha em: https://docs.google.com/forms/d/e/1FAIpQLSdknurpkcnCplYW07W63_5VzePxkZmNW2iwqJYTwARtztSJoQ/viewform Con chúc Cô và em một tuần mới vui vẻ ạ
A23: 22 | B23: 46278 | C23: 2 | D23: 10:00 - 12:00 | E23: Duy | F23: Economics IGCSE | G23: Workers: Why Some Jobs Pay More (Labor Economics) | H23: A-level Econs Châu Anh - 2026/09/13 04:57 CEST – Recording | I23: Checking | J23: Completed
A24: 23 | B24: 46280 | C24: 1.5 | D24: 16:00 - 17:30 | E24: Duy | F24: Economics IGCSE | G24: Review Section 2 | H24: A-level Econs Châu Anh - 2026/09/15 10:53 CEST – Recording | I24: Checking | J24: Completed
A25: 24 | B25: 46285 | C25: 2 | D25: 19:00 - 21:00 | E25: Duy | F25: Economics IGCSE | G25: Labor Union (Labor Economics) | H25: A-level Econs Châu Anh - 2026/09/20 09:56 CEST – Recording | I25: Checking | J25: Completed | K25: @Chi Vũ Dạ Cô ơi, con xin phép báo cáo tình hình học của em Châu Anh tuần này ạ: Buổi 1 (15/9): Em được học về Labor Union, đây là một mảng nữa của Labor Economics ạ. Em được học và tìm hiểu về incentive, reason tại sao cần có Union ạ. Buổi 2 (20/9): Em được review toàn bộ Section 3 bao gồm Banking, Household Economics và Labor Economics ạ Dạ vì em Châu Anh sẽ thi giữa kì vào tháng sau nên 2 tuần tiếp theo con sẽ dạy 3 buổi 1 tuần để dư ra thời gian ôn tập cho bé thêm nha Cô. Con chúc Cô và em buổi tối vui vẻ ạ!
A26: 25 | B26: 46286 | C26: 2 | D26: 19:00 - 21:00 | E26: Duy | F26: Economics IGCSE | G26: Firms - Small, Large, and Growing | H26: A-level Econs Châu Anh - 2026/09/21 13:55 CEST – Recording | I26: Checking | J26: Completed
A27: 26 | B27: 46288 | C27: 2 | D27: 19:00 - 21:00 | E27: Duy | F27: Economics IGCSE | G27: Review Section 3 | H27: A-level Econs - Châu Anh - 2026/09/23 13:55 CEST – Recording | I27: Checking | J27: Completed | K27: @Chi Vũ Dạ Cô ơi, con xin phép báo cáo tình hình học của em Châu Anh tuần này ạ: Buổi 1 (21/9): Em được học về Firms, tìm hiểu về intuition, operation, direction và strategy của từng loại công ty ạ. Buổi 2 (23/9) + Buổi 3 (25/9): Em được review lại phần Microeconomics để chuẩn bị thi giữa kỳ ạ @Eggtree nhớ làm bài nha em để cuối tuần mình sửa nhé. Con chúc Cô và em tuần mới vui vẻ ạ!
A28: 27 | B28: 46290 | C28: 2 | D28: 19:00 - 21:00 | E28: Duy | F28: Economics IGCSE | G28: Review Microeconomics (part 1) | H28: A-level Econs Châu Anh - 2026/09/25 13:55 CEST – Recording | I28: Checking | J28: Completed
A29: 28 | B29: 46297 | C29: 2 | D29: 19:00 - 21:00 | E29: Duy | F29: Economics IGCSE | G29: Review Microeconomics (part 2) | H29: A-level Econs Châu Anh - 2026/10/02 13:56 CEST – Recording | I29: Checking | J29: Completed | K29: @Chi Vũ Cô ơi dạ con xin phép update tình hình học tuần này của em Châu Anh nha ạ Buổi 1 (2/10): Em được con khảo bài phần Microeconomics để đi thi giữa kỳ, bao gồm tất cả lý thuyết liên quan và MCQ ạ Buổi 2 (4/10): Em được con chấm và chữa bài tại chỗ phần essay để chuẩn bị thi giữa kỳ ạ. Nhận thấy em còn chưa vững phần tính toán nên con và em sẽ tiếp tục ôn kỹ hơn phần này trong tuần tới ạ. @Eggtree ơi, a gửi thêm link để em luyện tập phần tính toán nhé https://docs.google.com/forms/d/11_g24XT_Y71SuTjshDneLQVHN43AGqwPKlaHaU3x4wM/edit Con chúc Cô và em một buổi tối vui vẻ ạ!
A30: 29 | B30: 46299 | C30: 2 | D30: 19:00 - 21:00 | E30: Duy | F30: Economics IGCSE | G30: Review Midterm (part 1) | H30: A-level Econs Châu Anh - 2026/10/04 13:25 CEST – Recording | I30: Checking | J30: Completed
A31: 30 | B31: 46304 | C31: 1.5 | D31: 20:00 - 21:30 | E31: Duy | F31: Economics IGCSE | G31: The Role of Government | H31: Acc em mất pro nên không recording được :( | I31: Checking | J31: Completed
A32: 31 | B32: 46306 | C32: 2 | D32: 15:00 - 17:00 | E32: Duy | F32: Economics IGCSE | G32: What Government Aims For | J32: Completed
A33: =IF(B33="","",ROW()-1)
A34: =IF(B34="","",ROW()-1)
A35: =IF(B35="","",ROW()-1)
A36: =IF(B36="","",ROW()-1)
A37: =IF(B37="","",ROW()-1)
A38: =IF(B38="","",ROW()-1)
A39: =IF(B39="","",ROW()-1)
A40: =IF(B40="","",ROW()-1)
...

Sheet Payment Summary
A1: Payment summary
A2: Set the payment period below. Only classes with status "Completed" inside the period are counted.
A4: Period start | C4: 46204
A5: Period end | C5: 46234
A7: Tutor | B7: Period | C7: Completed classes | D7: Number of hours | E7: Paid? | F7: Notes
A8: Duy | B8: 1/7 - 31/7 | C8: 9 | D8: =C8*1.5 -> 13.5 | E8: Yes | F8: Thanh toán 2 đợt = 10.700.000
A9: Duy | B9: 1/8 - 24/8 | C9: 7 | D9: =sum('Class Log'!C11:C17) -> 12.5 | E9: Yes
A10: Duy | B10: 27-Aug-26 - 11-Oct-26 | C10: =count('Class Log'!B18:B32) -> 15 | D10: =sum('Class Log'!C18:C32) -> 29 | E10: No | F10: Thanh toán Lần 1: 5 triệu
C11: =IF(A11="","",COUNTIFS('Class Log'!$E$2:$E$201,A11,'Class Log'!$J$2:$J$201,"Completed",'Class Log'!$B$2:$B$201,">="&$C$4,'Class Log'!$B$2:$B$201,"<="&$C$5))
C12: =IF(A12="","",COUNTIFS('Class Log'!$E$2:$E$201,A12,'Class Log'!$J$2:$J$201,"Completed",'Class Log'!$B$2:$B$201,">="&$C$4,'Class Log'!$B$2:$B$201,"<="&$C$5))
C13: =IF(A13="","",COUNTIFS('Class Log'!$E$2:$E$201,A13,'Class Log'!$J$2:$J$201,"Completed",'Class Log'!$B$2:$B$201,">="&$C$4,'Class Log'!$B$2:$B$201,"<="&$C$5))
C14: =IF(A14="","",COUNTIFS('Class Log'!$E$2:$E$201,A14,'Class Log'!$J$2:$J$201,"Completed",'Class Log'!$B$2:$B$201,">="&$C$4,'Class Log'!$B$2:$B$201,"<="&$C$5))
C15: =IF(A15="","",COUNTIFS('Class Log'!$E$2:$E$201,A15,'Class Log'!$J$2:$J$201,"Completed",'Class Log'!$B$2:$B$201,">="&$C$4,'Class Log'!$B$2:$B$201,"<="&$C$5))
C16: =IF(A16="","",COUNTIFS('Class Log'!$E$2:$E$201,A16,'Class Log'!$J$2:$J$201,"Completed",'Class Log'!$B$2:$B$201,">="&$C$4,'Class Log'!$B$2:$B$201,"<="&$C$5))
C17: =IF(A17="","",COUNTIFS('Class Log'!$E$2:$E$201,A17,'Class Log'!$J$2:$J$201,"Completed",'Class Log'!$B$2:$B$201,">="&$C$4,'Class Log'!$B$2:$B$201,"<="&$C$5))
C18: =IF(A18="","",COUNTIFS('Class Log'!$E$2:$E$201,A18,'Class Log'!$J$2:$J$201,"Completed",'Class Log'!$B$2:$B$201,">="&$C$4,'Class Log'!$B$2:$B$201,"<="&$C$5))
C19: =IF(A19="","",COUNTIFS('Class Log'!$E$2:$E$201,A19,'Class Log'!$J$2:$J$201,"Completed",'Class Log'!$B$2:$B$201,">="&$C$4,'Class Log'!$B$2:$B$201,"<="&$C$5))
C20: =IF(A20="","",COUNTIFS('Class Log'!$E$2:$E$201,A20,'Class Log'!$J$2:$J$201,"Completed",'Class Log'!$B$2:$B$201,">="&$C$4,'Class Log'!$B$2:$B$201,"<="&$C$5))
C21: =IF(A21="","",COUNTIFS('Class Log'!$E$2:$E$201,A21,'Class Log'!$J$2:$J$201,"Completed",'Class Log'!$B$2:$B$201,">="&$C$4,'Class Log'!$B$2:$B$201,"<="&$C$5))
C22: =IF(A22="","",COUNTIFS('Class Log'!$E$2:$E$201,A22,'Class Log'!$J$2:$J$201,"Completed",'Class Log'!$B$2:$B$201,">="&$C$4,'Class Log'!$B$2:$B$201,"<="&$C$5))
... C27: =IF(A27="","",COUNTIFS('Class Log'!$E$2:$E$201,A27,'Class Log'!$J$2:$J$201,"Completed",'Class Log'!$B$2:$B$201,">="&$C$4,'Class Log'!$B$2:$B$201,"<="&$C$5))
A28: TOTAL | C28: =SUM(C8:C27) -> 31
